[2024-07-13T18:37:11.306+0100] {local_task_job_runner.py:120} INFO - ::group::Pre task execution logs
[2024-07-13T18:37:11.350+0100] {taskinstance.py:2076} INFO - Dependencies all met for dep_context=non-requeueable deps ti=<TaskInstance: hhh.fit_prediction manual__2024-07-13T17:33:32.070840+00:00 [queued]>
[2024-07-13T18:37:11.549+0100] {taskinstance.py:2076} INFO - Dependencies all met for dep_context=requeueable deps ti=<TaskInstance: hhh.fit_prediction manual__2024-07-13T17:33:32.070840+00:00 [queued]>
[2024-07-13T18:37:11.550+0100] {taskinstance.py:2306} INFO - Starting attempt 1 of 1
[2024-07-13T18:37:11.563+0100] {taskinstance.py:2330} INFO - Executing <Task(_PythonDecoratedOperator): fit_prediction> on 2024-07-13 17:33:32.070840+00:00
[2024-07-13T18:37:11.582+0100] {logging_mixin.py:188} WARNING - /Library/Frameworks/Python.framework/Versions/3.12/lib/python3.12/site-packages/airflow/task/task_runner/standard_task_runner.py:61 DeprecationWarning: This process (pid=6715) is multi-threaded, use of fork() may lead to deadlocks in the child.
[2024-07-13T18:37:11.584+0100] {standard_task_runner.py:63} INFO - Started process 6727 to run task
[2024-07-13T18:37:11.584+0100] {standard_task_runner.py:90} INFO - Running: ['airflow', 'tasks', 'run', 'hhh', 'fit_prediction', 'manual__2024-07-13T17:33:32.070840+00:00', '--job-id', '11', '--raw', '--subdir', 'DAGS_FOLDER/dg1.py', '--cfg-path', '/var/folders/ml/zd6cs33j1gs1prd5lpns9pnc0000gn/T/tmp8zrqelks']
[2024-07-13T18:37:11.587+0100] {standard_task_runner.py:91} INFO - Job 11: Subtask fit_prediction
[2024-07-13T18:37:11.656+0100] {task_command.py:426} INFO - Running <TaskInstance: hhh.fit_prediction manual__2024-07-13T17:33:32.070840+00:00 [running]> on host MAKs-MacBook-Pro.local
[2024-07-13T18:37:11.828+0100] {taskinstance.py:2648} INFO - Exporting env vars: AIRFLOW_CTX_DAG_OWNER='airflow' AIRFLOW_CTX_DAG_ID='hhh' AIRFLOW_CTX_TASK_ID='fit_prediction' AIRFLOW_CTX_EXECUTION_DATE='2024-07-13T17:33:32.070840+00:00' AIRFLOW_CTX_TRY_NUMBER='1' AIRFLOW_CTX_DAG_RUN_ID='manual__2024-07-13T17:33:32.070840+00:00'
[2024-07-13T18:37:11.831+0100] {taskinstance.py:430} INFO - ::endgroup::
[2024-07-13T18:37:11.832+0100] {taskinstance.py:441} INFO - ::group::Post task execution logs
[2024-07-13T18:37:11.833+0100] {taskinstance.py:2905} ERROR - Task failed with exception
Traceback (most recent call last):
  File "/Library/Frameworks/Python.framework/Versions/3.12/lib/python3.12/site-packages/airflow/models/taskinstance.py", line 465, in _execute_task
    result = _execute_callable(context=context, **execute_callable_kwargs)
             ^^^^^^^^^^^^^^^^^^^^^^^^^^^^^^^^^^^^^^^^^^^^^^^^^^^^^^^^^^^^^
  File "/Library/Frameworks/Python.framework/Versions/3.12/lib/python3.12/site-packages/airflow/models/taskinstance.py", line 432, in _execute_callable
    return execute_callable(context=context, **execute_callable_kwargs)
           ^^^^^^^^^^^^^^^^^^^^^^^^^^^^^^^^^^^^^^^^^^^^^^^^^^^^^^^^^^^^
  File "/Library/Frameworks/Python.framework/Versions/3.12/lib/python3.12/site-packages/airflow/models/baseoperator.py", line 401, in wrapper
    return func(self, *args, **kwargs)
           ^^^^^^^^^^^^^^^^^^^^^^^^^^^
  File "/Library/Frameworks/Python.framework/Versions/3.12/lib/python3.12/site-packages/airflow/decorators/base.py", line 265, in execute
    return_value = super().execute(context)
                   ^^^^^^^^^^^^^^^^^^^^^^^^
  File "/Library/Frameworks/Python.framework/Versions/3.12/lib/python3.12/site-packages/airflow/models/baseoperator.py", line 401, in wrapper
    return func(self, *args, **kwargs)
           ^^^^^^^^^^^^^^^^^^^^^^^^^^^
  File "/Library/Frameworks/Python.framework/Versions/3.12/lib/python3.12/site-packages/airflow/operators/python.py", line 235, in execute
    return_value = self.execute_callable()
                   ^^^^^^^^^^^^^^^^^^^^^^^
  File "/Library/Frameworks/Python.framework/Versions/3.12/lib/python3.12/site-packages/airflow/operators/python.py", line 252, in execute_callable
    return self.python_callable(*self.op_args, **self.op_kwargs)
           ^^^^^^^^^^^^^^^^^^^^^^^^^^^^^^^^^^^^^^^^^^^^^^^^^^^^^
  File "/Users/mak/Desktop/Code_With_Me/Sentiment project/dags/dg1.py", line 81, in fit_prediction
    fit_data = fit_data[['Date', 'negative', 'positive', 'neutral', 'anger', 'disgust', 'fear', 'joy', 'sadness', 'surprise', 'others','Close']]
               ^^^^^^^^
UnboundLocalError: cannot access local variable 'fit_data' where it is not associated with a value
[2024-07-13T18:37:11.841+0100] {taskinstance.py:1206} INFO - Marking task as FAILED. dag_id=hhh, task_id=fit_prediction, run_id=manual__2024-07-13T17:33:32.070840+00:00, execution_date=20240713T173332, start_date=20240713T173711, end_date=20240713T173711
[2024-07-13T18:37:11.851+0100] {standard_task_runner.py:110} ERROR - Failed to execute job 11 for task fit_prediction (cannot access local variable 'fit_data' where it is not associated with a value; 6727)
[2024-07-13T18:37:11.890+0100] {local_task_job_runner.py:240} INFO - Task exited with return code 1
[2024-07-13T18:37:11.910+0100] {taskinstance.py:3503} INFO - 0 downstream tasks scheduled from follow-on schedule check
[2024-07-13T18:37:11.910+0100] {local_task_job_runner.py:222} INFO - ::endgroup::
